<?xml version="1.0" ?>
<robot name="braco" xmlns:xacro="http://www.ros.org/wiki/xacro">
    <link name="base">
        <inertial>
            <origin xyz="0.0 0.0 0.0" rpy="0.0 0.0 0.0"/>
            <mass value="5"/>
            <inertia ixx="0.0" ixy="0.0" ixz="0.0" iyy="0.0" iyz="0.0" izz="0.0"/>
        </inertial>
        <visual >
            <origin xyz="0.0 0.0 0.0" rpy="0.0 0.0 0.0"/>
            <geometry>
                <box size="0.50 0.60 0.70"/>
            </geometry>
            <material name="">
                <color rgba="255 0.0 0.0 1"/>
                <texture />
            </material>
        </visual>
        <collision>
            <origin xyz="0.0 0.0 0.0" rpy="0.0 0.0 0.0"/>
            <geometry>
                <box size="0.50 0.60 0.70"/>
            </geometry>
        </collision>
    </link>    

    <joint name="joint1" type="fixed">
        <origin xyz="0.184 0 0.39" rpy="0 0 0"/> <!-- Posiciona o link filho acima do link pai -->
        <parent link="base"/>
        <child link="base_braco"/>
    </joint>

    <link name="base_braco">
        <inertial>
            <origin xyz="0.0 0.0 0.0" rpy="0.0 0.0 0.0"/>
            <mass value="5"/>
            <inertia ixx="0.0" ixy="0.0" ixz="0.0" iyy="0.0" iyz="0.0" izz="0.0"/>
        </inertial>
        <visual >
            <origin xyz="0.0 0.0 0.0" rpy="0.0 0.0 0.0"/>
            <geometry>
                <box size="0.20 0.15 0.10"/>
            </geometry>
            <material name="">
                <color rgba="255 0.0 0.0 1"/>
                <texture />
            </material>
        </visual>
        <collision>
            <origin xyz="0.0 0.0 0.0" rpy="0.0 0.0 0.0"/>
            <geometry>
                <box size="0.15 0.20 0.10"/>
            </geometry>
        </collision>
    </link> 

    <joint name="revolute_joint" type="revolute">
        <parent link="base_braco"/>
        <child link="gira"/>
        <axis xyz="0 0 1"/>
        <origin xyz="0 0 0.2" rpy="0 0 0"/>
        <limit lower="-1.57" upper="1.57" effort="1000" velocity="1.0"/>
    </joint>
    

    <link name="gira">
        <inertial>
            <origin xyz="0.0 0.0 0.0" rpy="0.0 0.0 0.0"/>
            <mass value="5"/>
            <inertia ixx="0.0" ixy="0.0" ixz="0.0" iyy="0.0" iyz="0.0" izz="0.0"/>
        </inertial>
        <visual >
            <origin xyz="0.0 0.0 0.0" rpy="0.0 0.0 0.0"/>
            <geometry>
                <box size="0.05 0.05 0.40"/>
            </geometry>
            <material name="">
                <color rgba="255 0.0 0.0 1"/>
                <texture />
            </material>
        </visual>
        <collision>
            <origin xyz="0.0 0.0 0.0" rpy="0.0 0.0 0.0"/>
            <geometry>
                <box size="0.15 0.20 0.10"/>
            </geometry>
        </collision>
    </link> 

<joint name="teste" type="fixed">
        <origin xyz="0.03 0 0.2" rpy="0 0 0"/> <!-- Posiciona o link filho acima do link pai -->
        <parent link="gira"/>
        <child link="testegiro"/>
    </joint>

    <link name="testegiro">
        <inertial>
            <origin xyz="0.0 0.0 0.0" rpy="0.0 0.0 0.0"/>
            <mass value="5"/>
            <inertia ixx="0.0" ixy="0.0" ixz="0.0" iyy="0.0" iyz="0.0" izz="0.0"/>
        </inertial>
        <visual >
            <origin xyz="0.0 0.0 0.0" rpy="0.0 0.0 0.0"/>
            <geometry>
                <box size="0.1 0.03 0.10"/>
            </geometry>
            <material name="">
                <color rgba="255 0.0 0.0 1"/>
                <texture />
            </material>
        </visual>
        <collision>
            <origin xyz="0.0 0.0 0.0" rpy="0.0 0.0 0.0"/>
            <geometry>
                <box size="0.15 0.20 0.10"/>
            </geometry>
        </collision>
    </link> 
<transmission name="transmission_revolute_joint">
  <type>transmission_interface/SimpleTransmission</type>
  <joint name="revolute_joint">
    <hardwareInterface>EffortJointInterface</hardwareInterface>
  </joint>
  <actuator name="revolute_joint_motor">
    <mechanicalReduction>1</mechanicalReduction>
  </actuator>
</transmission>
</robot>
